<?xml version="1.0" ?>
<!-- =================================================================================== -->
<!-- |    This document was autogenerated by xacro from bbbot.xacro                    | -->
<!-- |    EDITING THIS FILE BY HAND IS NOT RECOMMENDED                                 | -->
<!-- =================================================================================== -->
<!-- Revolute-Revolute Manipulator -->
<robot name="bbbot" xmlns:xacro="http://www.ros.org/wiki/xacro">
    <gazebo>
    <plugin filename="libgazebo_ros_control.so" name="left_arm_ros_control">
      <robotNamespace>leftarm</robotNamespace>
      <!--robotSimType>gazebo_ros_control/DefaultRobotHWSim</robotSimType-->
    </plugin>
  </gazebo>
  <material name="black">
    <color rgba="0.0 0.0 0.0 1.0"/>
  </material>
  <material name="blue">
    <color rgba="0.0 0.0 0.8 1.0"/>
  </material>
  <material name="green">
    <color rgba="0.0 0.8 0.0 1.0"/>
  </material>
  <material name="grey">
    <color rgba="0.2 0.2 0.2 1.0"/>
  </material>
  <material name="orange">
    <color rgba="1.0 0.423529411765 0.0392156862745 1.0"/>
  </material>
  <material name="brown">
    <color rgba="0.870588235294 0.811764705882 0.764705882353 1.0"/>
  </material>
  <material name="red">
    <color rgba="0.8 0.0 0.0 1.0"/>
  </material>
  <material name="white">
    <color rgba="1.0 1.0 1.0 1.0"/>
  </material>
  <!-- Used for fixing robot to Gazebo 'base_link' -->
  <link name="world"/>
  <joint name="world__base_joint" type="fixed">
    <origin rpy="0 0 0" xyz="0 0 0"/>
    <parent link="world"/>
    <child link="stand_link"/>
  </joint>
  <link name="stand_link">
    <visual>
      <origin rpy="1.570796327 0 0" xyz="0 0 0"/>
      <geometry>
        <mesh filename="package://bbbot_description/meshes/visual/stand.stl"/>
      </geometry>
    </visual>
    <collision>
      <origin rpy="0 0 0" xyz="-0.3 -0.3 0"/>
      <geometry>
        <mesh filename="package://bbbot_description/meshes/collision/stand.stl"/>
      </geometry>
    </collision>
    <inertial>
      <origin rpy="0 0 0" xyz="0 0 0"/>
      <mass value="1000"/>
      <inertia ixx="100.0" ixy="0.0" ixz="0.0" iyy="100.0" iyz="0.0" izz="100.0"/>
    </inertial>
  </link>

  <!-- First element of the arm fixed to the parent -->
  <joint name="world_left_arm__base_joint" type="fixed">
    <origin rpy="-1.570796327 0 0" xyz="0.045 0.1665 1.525"/>
    <parent link="world"/>
    <child link="left_arm_shoulder_link"/>
  </joint>
  <!-- link 1 -->
  <link name="left_arm_shoulder_link">
    <collision>
      <origin rpy="0 0 3.141592654" xyz="0 0 0.063"/>
      <geometry>
        <box size="0.06 0.06 0.126"/>
      </geometry>
    </collision>
    <visual>
      <origin rpy="0 0 3.141592654" xyz="0 0 0"/>
      <geometry>
        <mesh filename="package://manipulator_description/meshes/link_1.stl" scale="0.001 0.001 0.001"/>
      </geometry>
      <material name="grey"/>
    </visual>
    <inertial>
      <origin rpy="0 0 0" xyz="0 0 0"/>
      <mass value="0.936"/>
      <inertia ixx="1.0" ixy="0.0" ixz="0.0" iyy="1.0" iyz="0.0" izz="1.0"/>
    </inertial>
  </link>
  <!-- Joint 1 -->
  <joint name="left_arm_shoulder_pan_joint" type="revolute">
    <parent link="left_arm_shoulder_link"/>
    <child link="left_arm_upper_arm_link"/>
    <origin rpy="0 0 0" xyz="0 0 0.126"/>
    <axis xyz="0 0 1"/>
    <limit effort="1000" lower="-1.8849555924" upper="1.8849555924" velocity="6.5"/>
    <dynamics damping="0.7"/>
  </joint>
  <!-- link 2 -->
  <link name="left_arm_upper_arm_link">
    <collision>
      <origin rpy="0 0 3.141592654" xyz="0 0 0.033"/>
      <geometry>
        <box size="0.07 0.15 0.08"/>
      </geometry>
    </collision>
    <visual>
      <origin rpy="0 0 3.141592654" xyz="0 0 -0.126"/>
      <geometry>
        <mesh filename="package://manipulator_description/meshes/link_2.stl" scale="0.001 0.001 0.001"/>
      </geometry>
      <material name="grey"/>
    </visual>
    <inertial>
      <origin rpy="0 0 0" xyz="0 0 0"/>
      <mass value="1.030"/>
      <inertia ixx="1.0" ixy="0.0" ixz="0.0" iyy="1.0" iyz="0.0" izz="1.0"/>
    </inertial>
  </link>
  <!-- Joint 2 -->
  <joint name="left_arm_shoulder_lift_joint" type="revolute">
    <parent link="left_arm_upper_arm_link"/>
    <child link="left_arm_forearm_link"/>
    <origin rpy="0 0 0" xyz="0 0 0.033"/>
    <axis xyz="0 1 0"/>
    <limit effort="1000" lower="-1.4137166943" upper="1.4137166943" velocity="6.5"/>
    <dynamics damping="0.7"/>
  </joint>
  <!-- link 3 -->
  <link name="left_arm_forearm_link">
    <collision>
      <origin rpy="0 0 3.141592654" xyz="0.02 0 0.15"/>
      <geometry>
        <box size="0.1 0.15 0.25"/>
      </geometry>
    </collision>
    <visual>
      <origin rpy="0 0 3.141592654" xyz="0 0 -0.159"/>
      <geometry>
        <mesh filename="package://manipulator_description/meshes/link_3.stl" scale="0.001 0.001 0.001"/>
      </geometry>
      <material name="grey"/>
    </visual>
    <inertial>
      <origin rpy="0 0 0" xyz="0 0 0"/>
      <mass value="1.404"/>
      <inertia ixx="1.0" ixy="0.0" ixz="0.0" iyy="1.0" iyz="0.0" izz="1.0"/>
    </inertial>
  </link>
  <!-- Joint 3 -->
  <joint name="left_arm_elbow_joint" type="revolute">
    <parent link="left_arm_forearm_link"/>
    <child link="left_arm_wrist_1_link"/>
    <origin rpy="0 0.7853981635 0" xyz="0.03 0.0 0.264"/>
    <axis xyz="0 1 0"/>
    <limit effort="1000" lower="-1.2566370616" upper="2.1991148578" velocity="6.5"/>
    <dynamics damping="0.7"/>
  </joint>
  <!-- link 4 -->
  <link name="left_arm_wrist_1_link">
    <collision>
      <origin rpy="0 0 3.141592654" xyz="-0.01 0.0 0.1"/>
      <geometry>
        <box size="0.1 0.15 0.25"/>
      </geometry>
    </collision>
    <visual>
      <origin rpy="0 0 3.141592654" xyz="-0.03 0 -0.423"/>
      <geometry>
        <mesh filename="package://manipulator_description/meshes/link_4.stl" scale="0.001 0.001 0.001"/>
      </geometry>
      <material name="grey"/>
    </visual>
    <inertial>
      <origin rpy="0 0 0" xyz="0 0 0"/>
      <mass value="1.236"/>
      <inertia ixx="1.0" ixy="0.0" ixz="0.0" iyy="1.0" iyz="0.0" izz="1.0"/>
    </inertial>
  </link>
  <!-- Joint 4 -->
  <joint name="left_arm_wrist_1_joint" type="revolute">
    <parent link="left_arm_wrist_1_link"/>
    <child link="left_arm_wrist_2_link"/>
    <origin rpy="0 0 0" xyz="-0.03 0.0 0.231"/>
    <axis xyz="0 0 1"/>
    <limit effort="1000" lower="-1.8849555924" upper="1.8849555924" velocity="6.5"/>
    <dynamics damping="0.7"/>
  </joint>
  <!-- link 5 -->
  <link name="left_arm_wrist_2_link">
    <collision>
      <origin rpy="0 0 3.141592654" xyz="0.0 0.0 0.03"/>
      <geometry>
        <box size="0.06 0.13 0.09"/>
      </geometry>
    </collision>
    <visual>
      <origin rpy="0 0 3.141592654" xyz="0 0 -0.654"/>
      <geometry>
        <mesh filename="package://manipulator_description/meshes/link_5.stl" scale="0.001 0.001 0.001"/>
      </geometry>
      <material name="grey"/>
    </visual>
    <inertial>
      <origin rpy="0 0 0" xyz="0 0 0"/>
      <mass value="0.491"/>
      <inertia ixx="1.0" ixy="0.0" ixz="0.0" iyy="1.0" iyz="0.0" izz="1.0"/>
    </inertial>
  </link>
  <!-- Joint 5 -->
  <joint name="left_arm_wrist_2_joint" type="revolute">
    <parent link="left_arm_wrist_2_link"/>
    <child link="left_arm_wrist_3_link"/>
    <origin rpy="0 0 0" xyz="0.0 0.0 0.027"/>
    <axis xyz="0 1 0"/>
    <limit effort="1000" lower="-1.4137166943" upper="1.4137166943" velocity="6.5"/>
    <dynamics damping="0.7"/>
  </joint>
  <!-- link 6 -->
  <link name="left_arm_wrist_3_link">
    <collision>
      <origin rpy="0 0 3.141592654" xyz="0.0 0.0 0.08"/>
      <geometry>
        <box size="0.07 0.07 0.08"/>
      </geometry>
    </collision>
    <visual>
      <origin rpy="0 0 3.141592654" xyz="0 0 -0.681"/>
      <geometry>
        <mesh filename="package://manipulator_description/meshes/link_6.stl" scale="0.001 0.001 0.001"/>
      </geometry>
      <material name="grey"/>
    </visual>
    <inertial>
      <origin rpy="0 0 0" xyz="0 0 0"/>
      <mass value="0.454"/>
      <inertia ixx="1.0" ixy="0.0" ixz="0.0" iyy="1.0" iyz="0.0" izz="1.0"/>
    </inertial>
  </link>
  <!-- Joint 6 -->
  <joint name="left_arm_wrist_3_joint" type="revolute">
    <parent link="left_arm_wrist_3_link"/>
    <child link="left_arm_ee_link"/>
    <origin rpy="0 0 0" xyz="0.0 0.0 0.123"/>
    <axis xyz="0 0 1"/>
    <limit effort="1000" lower="-1.8849555924" upper="1.8849555924" velocity="6.5"/>
    <dynamics damping="0.7"/>
  </joint>
  <!-- End Effector -->
  <link name="left_arm_ee_link">
    <collision>
      <origin rpy="0 0 0" xyz="0.0 0.0 0.0"/>
      <geometry>
        <box size="0.01 0.01 0.01"/>
      </geometry>
    </collision>
    <visual>
      <origin rpy="0 0 0" xyz="0.0 0.0 0.0"/>
      <geometry>
        <box size="0.01 0.01 0.01"/>
      </geometry>
      <material name="red"/>
    </visual>
    <inertial>
      <origin rpy="0 0 0" xyz="0.0 0.0 0.0"/>
      <mass value="0.001"/>
      <inertia ixx="1.0" ixy="0.0" ixz="0.0" iyy="1.0" iyz="0.0" izz="1.0"/>
    </inertial>
  </link>
  <transmission name="left_arm_shoulder_pan_trans">
    <type>transmission_interface/SimpleTransmission</type>
    <joint name="left_arm_shoulder_pan_joint">
      <hardwareInterface>PositionJointInterface</hardwareInterface>
    </joint>
    <actuator name="left_arm_shoulder_pan_motor">
      <hardwareInterface>PositionJointInterface</hardwareInterface>
      <mechanicalReduction>1</mechanicalReduction>
    </actuator>
  </transmission>
  <transmission name="left_arm_shoulder_lift_trans">
    <type>transmission_interface/SimpleTransmission</type>
    <joint name="left_arm_shoulder_lift_joint">
      <hardwareInterface>PositionJointInterface</hardwareInterface>
    </joint>
    <actuator name="left_arm_shoulder_lift_motor">
      <hardwareInterface>PositionJointInterface</hardwareInterface>
      <mechanicalReduction>1</mechanicalReduction>
    </actuator>
  </transmission>
  <transmission name="left_arm_elbow_trans">
    <type>transmission_interface/SimpleTransmission</type>
    <joint name="left_arm_elbow_joint">
      <hardwareInterface>PositionJointInterface</hardwareInterface>
    </joint>
    <actuator name="left_arm_elbow_motor">
      <hardwareInterface>PositionJointInterface</hardwareInterface>
      <mechanicalReduction>1</mechanicalReduction>
    </actuator>
  </transmission>
  <transmission name="left_arm_wrist_1_trans">
    <type>transmission_interface/SimpleTransmission</type>
    <joint name="left_arm_wrist_1_joint">
      <hardwareInterface>PositionJointInterface</hardwareInterface>
    </joint>
    <actuator name="left_arm_wrist_1_motor">
      <hardwareInterface>PositionJointInterface</hardwareInterface>
      <mechanicalReduction>1</mechanicalReduction>
    </actuator>
  </transmission>
  <transmission name="left_arm_wrist_2_trans">
    <type>transmission_interface/SimpleTransmission</type>
    <joint name="left_arm_wrist_2_joint">
      <hardwareInterface>PositionJointInterface</hardwareInterface>
    </joint>
    <actuator name="left_arm_wrist_2_motor">
      <hardwareInterface>PositionJointInterface</hardwareInterface>
      <mechanicalReduction>1</mechanicalReduction>
    </actuator>
  </transmission>
  <transmission name="left_arm_wrist_3_trans">
    <type>transmission_interface/SimpleTransmission</type>
    <joint name="left_arm_wrist_3_joint">
      <hardwareInterface>PositionJointInterface</hardwareInterface>
    </joint>
    <actuator name="left_arm_wrist_3_motor">
      <hardwareInterface>PositionJointInterface</hardwareInterface>
      <mechanicalReduction>1</mechanicalReduction>
    </actuator>
  </transmission>
</robot>

